Workbook

Sheet Сравнение
A1: Сравнение крипто-экосистем
A2: Обновлено 30.09.2026 скриптом collect.py. Голубые ячейки подтянуты из API (источник — в примечании к ячейке и на листе «Источники»), оранжевые — из API, но стоит проверить, жёлтые — ручной ввод. Зелёные колонки считаются автоматически.
A3: ВВОД ДАННЫХ | K3: ≥10% подсвечивается красным | M3: РАСЧЁТ (не трогать)
A4: Экосистема | B4: Категория | C4: Капитализация, $ млн | D4: FDV, $ млн | E4: TVL сейчас, $ млн | F4: TVL 6 мес назад, $ млн | G4: Активные адреса/день сейчас | H4: Активные адреса/день 6 мес назад | I4: Доход/комиссии за год, $ млн | J4: Активных разработчиков/мес | K4: Разлок за 6 мес, % предложения | L4: Инвесторы и команда, 1–5 | M4: Рост TVL 6м | N4: Рост адресов 6м | O4: Mcap / TVL | P4: Mcap / Доход | Q4: FDV / Mcap | R4: Итоговый балл, 0–100 | S4: Место
A5: Arbitrum | B5: L2 | C5: 1372.0642 | D5: 2022.031 | E5: 1440.3621 | F5: 1926.9911 | G5: 135118 | H5: 161371 | I5: 10.394479 | M5: =IF(OR(E5="",F5="",F5=0),"",E5/F5-1) | N5: =IF(OR(G5="",H5="",H5=0),"",G5/H5-1) | O5: =IF(OR(C5="",E5="",E5=0),"",C5/E5) | P5: =IF(OR(C5="",I5="",I5=0),"",C5/I5) | Q5: =IF(OR(C5="",D5="",C5=0),"",D5/C5) | R5: =Расчёт!K5 | S5: =IF(R5="","",RANK(R5,$R$5:$R$14))
A6: Optimism | B6: L2 | C6: 299.60174 | D6: 559.56066 | E6: 488.95365 | F6: 195.62457 | G6: 35710 | H6: 18509 | I6: 1.163975 | M6: =IF(OR(E6="",F6="",F6=0),"",E6/F6-1) | N6: =IF(OR(G6="",H6="",H6=0),"",G6/H6-1) | O6: =IF(OR(C6="",E6="",E6=0),"",C6/E6) | P6: =IF(OR(C6="",I6="",I6=0),"",C6/I6) | Q6: =IF(OR(C6="",D6="",C6=0),"",D6/C6) | R6: =Расчёт!K6 | S6: =IF(R6="","",RANK(R6,$R$5:$R$14))
A7: Base | B7: L2 | E7: 6361.8884 | F7: 4057.3668 | G7: 308996 | H7: 424000 | I7: 56.624755 | M7: =IF(OR(E7="",F7="",F7=0),"",E7/F7-1) | N7: =IF(OR(G7="",H7="",H7=0),"",G7/H7-1) | O7: =IF(OR(C7="",E7="",E7=0),"",C7/E7) | P7: =IF(OR(C7="",I7="",I7=0),"",C7/I7) | Q7: =IF(OR(C7="",D7="",C7=0),"",D7/C7) | R7: =Расчёт!K7 | S7: =IF(R7="","",RANK(R7,$R$5:$R$14))
A8: Mantle | B8: L2 | C8: 2303.632 | D8: 4338.504 | E8: 105.98936 | F8: 653.48033 | G8: 1300 | H8: 1499 | I8: 0.252569 | M8: =IF(OR(E8="",F8="",F8=0),"",E8/F8-1) | N8: =IF(OR(G8="",H8="",H8=0),"",G8/H8-1) | O8: =IF(OR(C8="",E8="",E8=0),"",C8/E8) | P8: =IF(OR(C8="",I8="",I8=0),"",C8/I8) | Q8: =IF(OR(C8="",D8="",C8=0),"",D8/C8) | R8: =Расчёт!K8 | S8: =IF(R8="","",RANK(R8,$R$5:$R$14))
A9: Starknet | B9: L2 | C9: 303.73817 | D9: 413.21516 | E9: 156.17777 | F9: 246.80338 | G9: 2613 | H9: 46550 | I9: 1.990909 | M9: =IF(OR(E9="",F9="",F9=0),"",E9/F9-1) | N9: =IF(OR(G9="",H9="",H9=0),"",G9/H9-1) | O9: =IF(OR(C9="",E9="",E9=0),"",C9/E9) | P9: =IF(OR(C9="",I9="",I9=0),"",C9/I9) | Q9: =IF(OR(C9="",D9="",C9=0),"",D9/C9) | R9: =Расчёт!K9 | S9: =IF(R9="","",RANK(R9,$R$5:$R$14))
A10: ZKsync | B10: L2 | C10: 131.74708 | D10: 255.78317 | E10: 15.90072 | F10: 22.377373 | G10: 2701 | H10: 3387 | I10: 0.498537 | M10: =IF(OR(E10="",F10="",F10=0),"",E10/F10-1) | N10: =IF(OR(G10="",H10="",H10=0),"",G10/H10-1) | O10: =IF(OR(C10="",E10="",E10=0),"",C10/E10) | P10: =IF(OR(C10="",I10="",I10=0),"",C10/I10) | Q10: =IF(OR(C10="",D10="",C10=0),"",D10/C10) | R10: =Расчёт!K10 | S10: =IF(R10="","",RANK(R10,$R$5:$R$14))
A11: Linea | B11: L2 | C11: 72.124611 | D11: 210.52941 | E11: 26.660603 | F11: 92.466761 | G11: 3226 | H11: 5470 | I11: 1.347858 | M11: =IF(OR(E11="",F11="",F11=0),"",E11/F11-1) | N11: =IF(OR(G11="",H11="",H11=0),"",G11/H11-1) | O11: =IF(OR(C11="",E11="",E11=0),"",C11/E11) | P11: =IF(OR(C11="",I11="",I11=0),"",C11/I11) | Q11: =IF(OR(C11="",D11="",C11=0),"",D11/C11) | R11: =Расчёт!K11 | S11: =IF(R11="","",RANK(R11,$R$5:$R$14))
A12: Scroll | B12: L2 | C12: 4.688116 | D12: 24.674296 | E12: 9.206047 | F12: 228.11529 | G12: 2640 | H12: 2662 | I12: 0.248046 | M12: =IF(OR(E12="",F12="",F12=0),"",E12/F12-1) | N12: =IF(OR(G12="",H12="",H12=0),"",G12/H12-1) | O12: =IF(OR(C12="",E12="",E12=0),"",C12/E12) | P12: =IF(OR(C12="",I12="",I12=0),"",C12/I12) | Q12: =IF(OR(C12="",D12="",C12=0),"",D12/C12) | R12: =Расчёт!K12 | S12: =IF(R12="","",RANK(R12,$R$5:$R$14))
M13: =IF(OR(E13="",F13="",F13=0),"",E13/F13-1) | N13: =IF(OR(G13="",H13="",H13=0),"",G13/H13-1) | O13: =IF(OR(C13="",E13="",E13=0),"",C13/E13) | P13: =IF(OR(C13="",I13="",I13=0),"",C13/I13) | Q13: =IF(OR(C13="",D13="",C13=0),"",D13/C13) | R13: =Расчёт!K13 | S13: =IF(R13="","",RANK(R13,$R$5:$R$14))
M14: =IF(OR(E14="",F14="",F14=0),"",E14/F14-1) | N14: =IF(OR(G14="",H14="",H14=0),"",G14/H14-1) | O14: =IF(OR(C14="",E14="",E14=0),"",C14/E14) | P14: =IF(OR(C14="",I14="",I14=0),"",C14/I14) | Q14: =IF(OR(C14="",D14="",C14=0),"",D14/C14) | R14: =Расчёт!K14 | S14: =IF(R14="","",RANK(R14,$R$5:$R$14))
A16: Легенда: зелёный — лучше среди сравниваемых, красный — хуже. Для Mcap/TVL, Mcap/Доход и FDV/Mcap меньше = лучше. Лидер по баллу подсвечен зелёным.
A17: Балл относительный: показывает, кто сильнее внутри твоей выборки, а не «покупать/не покупать». Сравнивай сети одной категории.

Sheet Расчёт
A1: Служебный лист: нормированные оценки 0–1 по каждой метрике
L3: Взвешенные оценки | T3: Учтённые веса
A4: Экосистема | B4: Рост TVL 6м | C4: Рост адресов 6м | D4: Mcap / TVL | E4: Mcap / Доход | F4: Активных разработчиков | G4: Разлок за 6 мес | H4: FDV / Mcap | I4: Инвесторы и команда | K4: Итог 0–100
A5: =IF(Сравнение!A5="","",Сравнение!A5) | B5: =IF(OR(NOT(ISNUMBER(Сравнение!M5)),COUNT(Сравнение!$M$5:$M$14)<2),"",IF(MAX(Сравнение!$M$5:$M$14)=MIN(Сравнение!$M$5:$M$14),0.5,(Сравнение!M5-MIN(Сравнение!$M$5:$M$14))/(MAX(Сравнение!$M$5:$M$14)-MIN(Сравнение!$M$5:$M$14)))) | C5: =IF(OR(NOT(ISNUMBER(Сравнение!N5)),COUNT(Сравнение!$N$5:$N$14)<2),"",IF(MAX(Сравнение!$N$5:$N$14)=MIN(Сравнение!$N$5:$N$14),0.5,(Сравнение!N5-MIN(Сравнение!$N$5:$N$14))/(MAX(Сравнение!$N$5:$N$14)-MIN(Сравнение!$N$5:$N$14)))) | D5: =IF(OR(NOT(ISNUMBER(Сравнение!O5)),COUNT(Сравнение!$O$5:$O$14)<2),"",IF(MAX(Сравнение!$O$5:$O$14)=MIN(Сравнение!$O$5:$O$14),0.5,(MAX(Сравнение!$O$5:$O$14)-Сравнение!O5)/(MAX(Сравнение!$O$5:$O$14)-MIN(Сравнение!$O$5:$O$14)))) | E5: =IF(OR(NOT(ISNUMBER(Сравнение!P5)),COUNT(Сравнение!$P$5:$P$14)<2),"",IF(MAX(Сравнение!$P$5:$P$14)=MIN(Сравнение!$P$5:$P$14),0.5,(MAX(Сравнение!$P$5:$P$14)-Сравнение!P5)/(MAX(Сравнение!$P$5:$P$14)-MIN(Сравнение!$P$5:$P$14)))) | F5: =IF(OR(NOT(ISNUMBER(Сравнение!J5)),COUNT(Сравнение!$J$5:$J$14)<2),"",IF(MAX(Сравнение!$J$5:$J$14)=MIN(Сравнение!$J$5:$J$14),0.5,(Сравнение!J5-MIN(Сравнение!$J$5:$J$14))/(MAX(Сравнение!$J$5:$J$14)-MIN(Сравнение!$J$5:$J$14)))) | G5: =IF(OR(NOT(ISNUMBER(Сравнение!K5)),COUNT(Сравнение!$K$5:$K$14)<2),"",IF(MAX(Сравнение!$K$5:$K$14)=MIN(Сравнение!$K$5:$K$14),0.5,(MAX(Сравнение!$K$5:$K$14)-Сравнение!K5)/(MAX(Сравнение!$K$5:$K$14)-MIN(Сравнение!$K$5:$K$14)))) | H5: =IF(OR(NOT(ISNUMBER(Сравнение!Q5)),COUNT(Сравнение!$Q$5:$Q$14)<2),"",IF(MAX(Сравнение!$Q$5:$Q$14)=MIN(Сравнение!$Q$5:$Q$14),0.5,(MAX(Сравнение!$Q$5:$Q$14)-Сравнение!Q5)/(MAX(Сравнение!$Q$5:$Q$14)-MIN(Сравнение!$Q$5:$Q$14)))) | I5: =IF(OR(NOT(ISNUMBER(Сравнение!L5)),COUNT(Сравнение!$L$5:$L$14)<2),"",IF(MAX(Сравнение!$L$5:$L$14)=MIN(Сравнение!$L$5:$L$14),0.5,(Сравнение!L5-MIN(Сравнение!$L$5:$L$14))/(MAX(Сравнение!$L$5:$L$14)-MIN(Сравнение!$L$5:$L$14)))) | K5: =IF(OR(Сравнение!A5="",SUM(T5:AA5)=0),"",100*SUM(L5:S5)/SUM(T5:AA5)) | L5: =IF(ISNUMBER(B5),B5*Веса!$B$4,0) | M5: =IF(ISNUMBER(C5),C5*Веса!$B$5,0) | N5: =IF(ISNUMBER(D5),D5*Веса!$B$6,0) | O5: =IF(ISNUMBER(E5),E5*Веса!$B$7,0) | P5: =IF(ISNUMBER(F5),F5*Веса!$B$8,0) | Q5: =IF(ISNUMBER(G5),G5*Веса!$B$9,0) | R5: =IF(ISNUMBER(H5),H5*Веса!$B$10,0) | S5: =IF(ISNUMBER(I5),I5*Веса!$B$11,0) | T5: =IF(ISNUMBER(B5),Веса!$B$4,0) | U5: =IF(ISNUMBER(C5),Веса!$B$5,0) | V5: =IF(ISNUMBER(D5),Веса!$B$6,0) | W5: =IF(ISNUMBER(E5),Веса!$B$7,0) | X5: =IF(ISNUMBER(F5),Веса!$B$8,0) | Y5: =IF(ISNUMBER(G5),Веса!$B$9,0) | Z5: =IF(ISNUMBER(H5),Веса!$B$10,0) | AA5: =IF(ISNUMBER(I5),Веса!$B$11,0)
A6: =IF(Сравнение!A6="","",Сравнение!A6) | B6: =IF(OR(NOT(ISNUMBER(Сравнение!M6)),COUNT(Сравнение!$M$5:$M$14)<2),"",IF(MAX(Сравнение!$M$5:$M$14)=MIN(Сравнение!$M$5:$M$14),0.5,(Сравнение!M6-MIN(Сравнение!$M$5:$M$14))/(MAX(Сравнение!$M$5:$M$14)-MIN(Сравнение!$M$5:$M$14)))) | C6: =IF(OR(NOT(ISNUMBER(Сравнение!N6)),COUNT(Сравнение!$N$5:$N$14)<2),"",IF(MAX(Сравнение!$N$5:$N$14)=MIN(Сравнение!$N$5:$N$14),0.5,(Сравнение!N6-MIN(Сравнение!$N$5:$N$14))/(MAX(Сравнение!$N$5:$N$14)-MIN(Сравнение!$N$5:$N$14)))) | D6: =IF(OR(NOT(ISNUMBER(Сравнение!O6)),COUNT(Сравнение!$O$5:$O$14)<2),"",IF(MAX(Сравнение!$O$5:$O$14)=MIN(Сравнение!$O$5:$O$14),0.5,(MAX(Сравнение!$O$5:$O$14)-Сравнение!O6)/(MAX(Сравнение!$O$5:$O$14)-MIN(Сравнение!$O$5:$O$14)))) | E6: =IF(OR(NOT(ISNUMBER(Сравнение!P6)),COUNT(Сравнение!$P$5:$P$14)<2),"",IF(MAX(Сравнение!$P$5:$P$14)=MIN(Сравнение!$P$5:$P$14),0.5,(MAX(Сравнение!$P$5:$P$14)-Сравнение!P6)/(MAX(Сравнение!$P$5:$P$14)-MIN(Сравнение!$P$5:$P$14)))) | F6: =IF(OR(NOT(ISNUMBER(Сравнение!J6)),COUNT(Сравнение!$J$5:$J$14)<2),"",IF(MAX(Сравнение!$J$5:$J$14)=MIN(Сравнение!$J$5:$J$14),0.5,(Сравнение!J6-MIN(Сравнение!$J$5:$J$14))/(MAX(Сравнение!$J$5:$J$14)-MIN(Сравнение!$J$5:$J$14)))) | G6: =IF(OR(NOT(ISNUMBER(Сравнение!K6)),COUNT(Сравнение!$K$5:$K$14)<2),"",IF(MAX(Сравнение!$K$5:$K$14)=MIN(Сравнение!$K$5:$K$14),0.5,(MAX(Сравнение!$K$5:$K$14)-Сравнение!K6)/(MAX(Сравнение!$K$5:$K$14)-MIN(Сравнение!$K$5:$K$14)))) | H6: =IF(OR(NOT(ISNUMBER(Сравнение!Q6)),COUNT(Сравнение!$Q$5:$Q$14)<2),"",IF(MAX(Сравнение!$Q$5:$Q$14)=MIN(Сравнение!$Q$5:$Q$14),0.5,(MAX(Сравнение!$Q$5:$Q$14)-Сравнение!Q6)/(MAX(Сравнение!$Q$5:$Q$14)-MIN(Сравнение!$Q$5:$Q$14)))) | I6: =IF(OR(NOT(ISNUMBER(Сравнение!L6)),COUNT(Сравнение!$L$5:$L$14)<2),"",IF(MAX(Сравнение!$L$5:$L$14)=MIN(Сравнение!$L$5:$L$14),0.5,(Сравнение!L6-MIN(Сравнение!$L$5:$L$14))/(MAX(Сравнение!$L$5:$L$14)-MIN(Сравнение!$L$5:$L$14)))) | K6: =IF(OR(Сравнение!A6="",SUM(T6:AA6)=0),"",100*SUM(L6:S6)/SUM(T6:AA6)) | L6: =IF(ISNUMBER(B6),B6*Веса!$B$4,0) | M6: =IF(ISNUMBER(C6),C6*Веса!$B$5,0) | N6: =IF(ISNUMBER(D6),D6*Веса!$B$6,0) | O6: =IF(ISNUMBER(E6),E6*Веса!$B$7,0) | P6: =IF(ISNUMBER(F6),F6*Веса!$B$8,0) | Q6: =IF(ISNUMBER(G6),G6*Веса!$B$9,0) | R6: =IF(ISNUMBER(H6),H6*Веса!$B$10,0) | S6: =IF(ISNUMBER(I6),I6*Веса!$B$11,0) | T6: =IF(ISNUMBER(B6),Веса!$B$4,0) | U6: =IF(ISNUMBER(C6),Веса!$B$5,0) | V6: =IF(ISNUMBER(D6),Веса!$B$6,0) | W6: =IF(ISNUMBER(E6),Веса!$B$7,0) | X6: =IF(ISNUMBER(F6),Веса!$B$8,0) | Y6: =IF(ISNUMBER(G6),Веса!$B$9,0) | Z6: =IF(ISNUMBER(H6),Веса!$B$10,0) | AA6: =IF(ISNUMBER(I6),Веса!$B$11,0)
A7: =IF(Сравнение!A7="","",Сравнение!A7) | B7: =IF(OR(NOT(ISNUMBER(Сравнение!M7)),COUNT(Сравнение!$M$5:$M$14)<2),"",IF(MAX(Сравнение!$M$5:$M$14)=MIN(Сравнение!$M$5:$M$14),0.5,(Сравнение!M7-MIN(Сравнение!$M$5:$M$14))/(MAX(Сравнение!$M$5:$M$14)-MIN(Сравнение!$M$5:$M$14)))) | C7: =IF(OR(NOT(ISNUMBER(Сравнение!N7)),COUNT(Сравнение!$N$5:$N$14)<2),"",IF(MAX(Сравнение!$N$5:$N$14)=MIN(Сравнение!$N$5:$N$14),0.5,(Сравнение!N7-MIN(Сравнение!$N$5:$N$14))/(MAX(Сравнение!$N$5:$N$14)-MIN(Сравнение!$N$5:$N$14)))) | D7: =IF(OR(NOT(ISNUMBER(Сравнение!O7)),COUNT(Сравнение!$O$5:$O$14)<2),"",IF(MAX(Сравнение!$O$5:$O$14)=MIN(Сравнение!$O$5:$O$14),0.5,(MAX(Сравнение!$O$5:$O$14)-Сравнение!O7)/(MAX(Сравнение!$O$5:$O$14)-MIN(Сравнение!$O$5:$O$14)))) | E7: =IF(OR(NOT(ISNUMBER(Сравнение!P7)),COUNT(Сравнение!$P$5:$P$14)<2),"",IF(MAX(Сравнение!$P$5:$P$14)=MIN(Сравнение!$P$5:$P$14),0.5,(MAX(Сравнение!$P$5:$P$14)-Сравнение!P7)/(MAX(Сравнение!$P$5:$P$14)-MIN(Сравнение!$P$5:$P$14)))) | F7: =IF(OR(NOT(ISNUMBER(Сравнение!J7)),COUNT(Сравнение!$J$5:$J$14)<2),"",IF(MAX(Сравнение!$J$5:$J$14)=MIN(Сравнение!$J$5:$J$14),0.5,(Сравнение!J7-MIN(Сравнение!$J$5:$J$14))/(MAX(Сравнение!$J$5:$J$14)-MIN(Сравнение!$J$5:$J$14)))) | G7: =IF(OR(NOT(ISNUMBER(Сравнение!K7)),COUNT(Сравнение!$K$5:$K$14)<2),"",IF(MAX(Сравнение!$K$5:$K$14)=MIN(Сравнение!$K$5:$K$14),0.5,(MAX(Сравнение!$K$5:$K$14)-Сравнение!K7)/(MAX(Сравнение!$K$5:$K$14)-MIN(Сравнение!$K$5:$K$14)))) | H7: =IF(OR(NOT(ISNUMBER(Сравнение!Q7)),COUNT(Сравнение!$Q$5:$Q$14)<2),"",IF(MAX(Сравнение!$Q$5:$Q$14)=MIN(Сравнение!$Q$5:$Q$14),0.5,(MAX(Сравнение!$Q$5:$Q$14)-Сравнение!Q7)/(MAX(Сравнение!$Q$5:$Q$14)-MIN(Сравнение!$Q$5:$Q$14)))) | I7: =IF(OR(NOT(ISNUMBER(Сравнение!L7)),COUNT(Сравнение!$L$5:$L$14)<2),"",IF(MAX(Сравнение!$L$5:$L$14)=MIN(Сравнение!$L$5:$L$14),0.5,(Сравнение!L7-MIN(Сравнение!$L$5:$L$14))/(MAX(Сравнение!$L$5:$L$14)-MIN(Сравнение!$L$5:$L$14)))) | K7: =IF(OR(Сравнение!A7="",SUM(T7:AA7)=0),"",100*SUM(L7:S7)/SUM(T7:AA7)) | L7: =IF(ISNUMBER(B7),B7*Веса!$B$4,0) | M7: =IF(ISNUMBER(C7),C7*Веса!$B$5,0) | N7: =IF(ISNUMBER(D7),D7*Веса!$B$6,0) | O7: =IF(ISNUMBER(E7),E7*Веса!$B$7,0) | P7: =IF(ISNUMBER(F7),F7*Веса!$B$8,0) | Q7: =IF(ISNUMBER(G7),G7*Веса!$B$9,0) | R7: =IF(ISNUMBER(H7),H7*Веса!$B$10,0) | S7: =IF(ISNUMBER(I7),I7*Веса!$B$11,0) | T7: =IF(ISNUMBER(B7),Веса!$B$4,0) | U7: =IF(ISNUMBER(C7),Веса!$B$5,0) | V7: =IF(ISNUMBER(D7),Веса!$B$6,0) | W7: =IF(ISNUMBER(E7),Веса!$B$7,0) | X7: =IF(ISNUMBER(F7),Веса!$B$8,0) | Y7: =IF(ISNUMBER(G7),Веса!$B$9,0) | Z7: =IF(ISNUMBER(H7),Веса!$B$10,0) | AA7: =IF(ISNUMBER(I7),Веса!$B$11,0)
A8: =IF(Сравнение!A8="","",Сравнение!A8) | B8: =IF(OR(NOT(ISNUMBER(Сравнение!M8)),COUNT(Сравнение!$M$5:$M$14)<2),"",IF(MAX(Сравнение!$M$5:$M$14)=MIN(Сравнение!$M$5:$M$14),0.5,(Сравнение!M8-MIN(Сравнение!$M$5:$M$14))/(MAX(Сравнение!$M$5:$M$14)-MIN(Сравнение!$M$5:$M$14)))) | C8: =IF(OR(NOT(ISNUMBER(Сравнение!N8)),COUNT(Сравнение!$N$5:$N$14)<2),"",IF(MAX(Сравнение!$N$5:$N$14)=MIN(Сравнение!$N$5:$N$14),0.5,(Сравнение!N8-MIN(Сравнение!$N$5:$N$14))/(MAX(Сравнение!$N$5:$N$14)-MIN(Сравнение!$N$5:$N$14)))) | D8: =IF(OR(NOT(ISNUMBER(Сравнение!O8)),COUNT(Сравнение!$O$5:$O$14)<2),"",IF(MAX(Сравнение!$O$5:$O$14)=MIN(Сравнение!$O$5:$O$14),0.5,(MAX(Сравнение!$O$5:$O$14)-Сравнение!O8)/(MAX(Сравнение!$O$5:$O$14)-MIN(Сравнение!$O$5:$O$14)))) | E8: =IF(OR(NOT(ISNUMBER(Сравнение!P8)),COUNT(Сравнение!$P$5:$P$14)<2),"",IF(MAX(Сравнение!$P$5:$P$14)=MIN(Сравнение!$P$5:$P$14),0.5,(MAX(Сравнение!$P$5:$P$14)-Сравнение!P8)/(MAX(Сравнение!$P$5:$P$14)-MIN(Сравнение!$P$5:$P$14)))) | F8: =IF(OR(NOT(ISNUMBER(Сравнение!J8)),COUNT(Сравнение!$J$5:$J$14)<2),"",IF(MAX(Сравнение!$J$5:$J$14)=MIN(Сравнение!$J$5:$J$14),0.5,(Сравнение!J8-MIN(Сравнение!$J$5:$J$14))/(MAX(Сравнение!$J$5:$J$14)-MIN(Сравнение!$J$5:$J$14)))) | G8: =IF(OR(NOT(ISNUMBER(Сравнение!K8)),COUNT(Сравнение!$K$5:$K$14)<2),"",IF(MAX(Сравнение!$K$5:$K$14)=MIN(Сравнение!$K$5:$K$14),0.5,(MAX(Сравнение!$K$5:$K$14)-Сравнение!K8)/(MAX(Сравнение!$K$5:$K$14)-MIN(Сравнение!$K$5:$K$14)))) | H8: =IF(OR(NOT(ISNUMBER(Сравнение!Q8)),COUNT(Сравнение!$Q$5:$Q$14)<2),"",IF(MAX(Сравнение!$Q$5:$Q$14)=MIN(Сравнение!$Q$5:$Q$14),0.5,(MAX(Сравнение!$Q$5:$Q$14)-Сравнение!Q8)/(MAX(Сравнение!$Q$5:$Q$14)-MIN(Сравнение!$Q$5:$Q$14)))) | I8: =IF(OR(NOT(ISNUMBER(Сравнение!L8)),COUNT(Сравнение!$L$5:$L$14)<2),"",IF(MAX(Сравнение!$L$5:$L$14)=MIN(Сравнение!$L$5:$L$14),0.5,(Сравнение!L8-MIN(Сравнение!$L$5:$L$14))/(MAX(Сравнение!$L$5:$L$14)-MIN(Сравнение!$L$5:$L$14)))) | K8: =IF(OR(Сравнение!A8="",SUM(T8:AA8)=0),"",100*SUM(L8:S8)/SUM(T8:AA8)) | L8: =IF(ISNUMBER(B8),B8*Веса!$B$4,0) | M8: =IF(ISNUMBER(C8),C8*Веса!$B$5,0) | N8: =IF(ISNUMBER(D8),D8*Веса!$B$6,0) | O8: =IF(ISNUMBER(E8),E8*Веса!$B$7,0) | P8: =IF(ISNUMBER(F8),F8*Веса!$B$8,0) | Q8: =IF(ISNUMBER(G8),G8*Веса!$B$9,0) | R8: =IF(ISNUMBER(H8),H8*Веса!$B$10,0) | S8: =IF(ISNUMBER(I8),I8*Веса!$B$11,0) | T8: =IF(ISNUMBER(B8),Веса!$B$4,0) | U8: =IF(ISNUMBER(C8),Веса!$B$5,0) | V8: =IF(ISNUMBER(D8),Веса!$B$6,0) | W8: =IF(ISNUMBER(E8),Веса!$B$7,0) | X8: =IF(ISNUMBER(F8),Веса!$B$8,0) | Y8: =IF(ISNUMBER(G8),Веса!$B$9,0) | Z8: =IF(ISNUMBER(H8),Веса!$B$10,0) | AA8: =IF(ISNUMBER(I8),Веса!$B$11,0)
A9: =IF(Сравнение!A9="","",Сравнение!A9) | B9: =IF(OR(NOT(ISNUMBER(Сравнение!M9)),COUNT(Сравнение!$M$5:$M$14)<2),"",IF(MAX(Сравнение!$M$5:$M$14)=MIN(Сравнение!$M$5:$M$14),0.5,(Сравнение!M9-MIN(Сравнение!$M$5:$M$14))/(MAX(Сравнение!$M$5:$M$14)-MIN(Сравнение!$M$5:$M$14)))) | C9: =IF(OR(NOT(ISNUMBER(Сравнение!N9)),COUNT(Сравнение!$N$5:$N$14)<2),"",IF(MAX(Сравнение!$N$5:$N$14)=MIN(Сравнение!$N$5:$N$14),0.5,(Сравнение!N9-MIN(Сравнение!$N$5:$N$14))/(MAX(Сравнение!$N$5:$N$14)-MIN(Сравнение!$N$5:$N$14)))) | D9: =IF(OR(NOT(ISNUMBER(Сравнение!O9)),COUNT(Сравнение!$O$5:$O$14)<2),"",IF(MAX(Сравнение!$O$5:$O$14)=MIN(Сравнение!$O$5:$O$14),0.5,(MAX(Сравнение!$O$5:$O$14)-Сравнение!O9)/(MAX(Сравнение!$O$5:$O$14)-MIN(Сравнение!$O$5:$O$14)))) | E9: =IF(OR(NOT(ISNUMBER(Сравнение!P9)),COUNT(Сравнение!$P$5:$P$14)<2),"",IF(MAX(Сравнение!$P$5:$P$14)=MIN(Сравнение!$P$5:$P$14),0.5,(MAX(Сравнение!$P$5:$P$14)-Сравнение!P9)/(MAX(Сравнение!$P$5:$P$14)-MIN(Сравнение!$P$5:$P$14)))) | F9: =IF(OR(NOT(ISNUMBER(Сравнение!J9)),COUNT(Сравнение!$J$5:$J$14)<2),"",IF(MAX(Сравнение!$J$5:$J$14)=MIN(Сравнение!$J$5:$J$14),0.5,(Сравнение!J9-MIN(Сравнение!$J$5:$J$14))/(MAX(Сравнение!$J$5:$J$14)-MIN(Сравнение!$J$5:$J$14)))) | G9: =IF(OR(NOT(ISNUMBER(Сравнение!K9)),COUNT(Сравнение!$K$5:$K$14)<2),"",IF(MAX(Сравнение!$K$5:$K$14)=MIN(Сравнение!$K$5:$K$14),0.5,(MAX(Сравнение!$K$5:$K$14)-Сравнение!K9)/(MAX(Сравнение!$K$5:$K$14)-MIN(Сравнение!$K$5:$K$14)))) | H9: =IF(OR(NOT(ISNUMBER(Сравнение!Q9)),COUNT(Сравнение!$Q$5:$Q$14)<2),"",IF(MAX(Сравнение!$Q$5:$Q$14)=MIN(Сравнение!$Q$5:$Q$14),0.5,(MAX(Сравнение!$Q$5:$Q$14)-Сравнение!Q9)/(MAX(Сравнение!$Q$5:$Q$14)-MIN(Сравнение!$Q$5:$Q$14)))) | I9: =IF(OR(NOT(ISNUMBER(Сравнение!L9)),COUNT(Сравнение!$L$5:$L$14)<2),"",IF(MAX(Сравнение!$L$5:$L$14)=MIN(Сравнение!$L$5:$L$14),0.5,(Сравнение!L9-MIN(Сравнение!$L$5:$L$14))/(MAX(Сравнение!$L$5:$L$14)-MIN(Сравнение!$L$5:$L$14)))) | K9: =IF(OR(Сравнение!A9="",SUM(T9:AA9)=0),"",100*SUM(L9:S9)/SUM(T9:AA9)) | L9: =IF(ISNUMBER(B9),B9*Веса!$B$4,0) | M9: =IF(ISNUMBER(C9),C9*Веса!$B$5,0) | N9: =IF(ISNUMBER(D9),D9*Веса!$B$6,0) | O9: =IF(ISNUMBER(E9),E9*Веса!$B$7,0) | P9: =IF(ISNUMBER(F9),F9*Веса!$B$8,0) | Q9: =IF(ISNUMBER(G9),G9*Веса!$B$9,0) | R9: =IF(ISNUMBER(H9),H9*Веса!$B$10,0) | S9: =IF(ISNUMBER(I9),I9*Веса!$B$11,0) | T9: =IF(ISNUMBER(B9),Веса!$B$4,0) | U9: =IF(ISNUMBER(C9),Веса!$B$5,0) | V9: =IF(ISNUMBER(D9),Веса!$B$6,0) | W9: =IF(ISNUMBER(E9),Веса!$B$7,0) | X9: =IF(ISNUMBER(F9),Веса!$B$8,0) | Y9: =IF(ISNUMBER(G9),Веса!$B$9,0) | Z9: =IF(ISNUMBER(H9),Веса!$B$10,0) | AA9: =IF(ISNUMBER(I9),Веса!$B$11,0)
A10: =IF(Сравнение!A10="","",Сравнение!A10) | B10: =IF(OR(NOT(ISNUMBER(Сравнение!M10)),COUNT(Сравнение!$M$5:$M$14)<2),"",IF(MAX(Сравнение!$M$5:$M$14)=MIN(Сравнение!$M$5:$M$14),0.5,(Сравнение!M10-MIN(Сравнение!$M$5:$M$14))/(MAX(Сравнение!$M$5:$M$14)-MIN(Сравнение!$M$5:$M$14)))) | C10: =IF(OR(NOT(ISNUMBER(Сравнение!N10)),COUNT(Сравнение!$N$5:$N$14)<2),"",IF(MAX(Сравнение!$N$5:$N$14)=MIN(Сравнение!$N$5:$N$14),0.5,(Сравнение!N10-MIN(Сравнение!$N$5:$N$14))/(MAX(Сравнение!$N$5:$N$14)-MIN(Сравнение!$N$5:$N$14)))) | D10: =IF(OR(NOT(ISNUMBER(Сравнение!O10)),COUNT(Сравнение!$O$5:$O$14)<2),"",IF(MAX(Сравнение!$O$5:$O$14)=MIN(Сравнение!$O$5:$O$14),0.5,(MAX(Сравнение!$O$5:$O$14)-Сравнение!O10)/(MAX(Сравнение!$O$5:$O$14)-MIN(Сравнение!$O$5:$O$14)))) | E10: =IF(OR(NOT(ISNUMBER(Сравнение!P10)),COUNT(Сравнение!$P$5:$P$14)<2),"",IF(MAX(Сравнение!$P$5:$P$14)=MIN(Сравнение!$P$5:$P$14),0.5,(MAX(Сравнение!$P$5:$P$14)-Сравнение!P10)/(MAX(Сравнение!$P$5:$P$14)-MIN(Сравнение!$P$5:$P$14)))) | F10: =IF(OR(NOT(ISNUMBER(Сравнение!J10)),COUNT(Сравнение!$J$5:$J$14)<2),"",IF(MAX(Сравнение!$J$5:$J$14)=MIN(Сравнение!$J$5:$J$14),0.5,(Сравнение!J10-MIN(Сравнение!$J$5:$J$14))/(MAX(Сравнение!$J$5:$J$14)-MIN(Сравнение!$J$5:$J$14)))) | G10: =IF(OR(NOT(ISNUMBER(Сравнение!K10)),COUNT(Сравнение!$K$5:$K$14)<2),"",IF(MAX(Сравнение!$K$5:$K$14)=MIN(Сравнение!$K$5:$K$14),0.5,(MAX(Сравнение!$K$5:$K$14)-Сравнение!K10)/(MAX(Сравнение!$K$5:$K$14)-MIN(Сравнение!$K$5:$K$14)))) | H10: =IF(OR(NOT(ISNUMBER(Сравнение!Q10)),COUNT(Сравнение!$Q$5:$Q$14)<2),"",IF(MAX(Сравнение!$Q$5:$Q$14)=MIN(Сравнение!$Q$5:$Q$14),0.5,(MAX(Сравнение!$Q$5:$Q$14)-Сравнение!Q10)/(MAX(Сравнение!$Q$5:$Q$14)-MIN(Сравнение!$Q$5:$Q$14)))) | I10: =IF(OR(NOT(ISNUMBER(Сравнение!L10)),COUNT(Сравнение!$L$5:$L$14)<2),"",IF(MAX(Сравнение!$L$5:$L$14)=MIN(Сравнение!$L$5:$L$14),0.5,(Сравнение!L10-MIN(Сравнение!$L$5:$L$14))/(MAX(Сравнение!$L$5:$L$14)-MIN(Сравнение!$L$5:$L$14)))) | K10: =IF(OR(Сравнение!A10="",SUM(T10:AA10)=0),"",100*SUM(L10:S10)/SUM(T10:AA10)) | L10: =IF(ISNUMBER(B10),B10*Веса!$B$4,0) | M10: =IF(ISNUMBER(C10),C10*Веса!$B$5,0) | N10: =IF(ISNUMBER(D10),D10*Веса!$B$6,0) | O10: =IF(ISNUMBER(E10),E10*Веса!$B$7,0) | P10: =IF(ISNUMBER(F10),F10*Веса!$B$8,0) | Q10: =IF(ISNUMBER(G10),G10*Веса!$B$9,0) | R10: =IF(ISNUMBER(H10),H10*Веса!$B$10,0) | S10: =IF(ISNUMBER(I10),I10*Веса!$B$11,0) | T10: =IF(ISNUMBER(B10),Веса!$B$4,0) | U10: =IF(ISNUMBER(C10),Веса!$B$5,0) | V10: =IF(ISNUMBER(D10),Веса!$B$6,0) | W10: =IF(ISNUMBER(E10),Веса!$B$7,0) | X10: =IF(ISNUMBER(F10),Веса!$B$8,0) | Y10: =IF(ISNUMBER(G10),Веса!$B$9,0) | Z10: =IF(ISNUMBER(H10),Веса!$B$10,0) | AA10: =IF(ISNUMBER(I10),Веса!$B$11,0)
A11: =IF(Сравнение!A11="","",Сравнение!A11) | B11: =IF(OR(NOT(ISNUMBER(Сравнение!M11)),COUNT(Сравнение!$M$5:$M$14)<2),"",IF(MAX(Сравнение!$M$5:$M$14)=MIN(Сравнение!$M$5:$M$14),0.5,(Сравнение!M11-MIN(Сравнение!$M$5:$M$14))/(MAX(Сравнение!$M$5:$M$14)-MIN(Сравнение!$M$5:$M$14)))) | C11: =IF(OR(NOT(ISNUMBER(Сравнение!N11)),COUNT(Сравнение!$N$5:$N$14)<2),"",IF(MAX(Сравнение!$N$5:$N$14)=MIN(Сравнение!$N$5:$N$14),0.5,(Сравнение!N11-MIN(Сравнение!$N$5:$N$14))/(MAX(Сравнение!$N$5:$N$14)-MIN(Сравнение!$N$5:$N$14)))) | D11: =IF(OR(NOT(ISNUMBER(Сравнение!O11)),COUNT(Сравнение!$O$5:$O$14)<2),"",IF(MAX(Сравнение!$O$5:$O$14)=MIN(Сравнение!$O$5:$O$14),0.5,(MAX(Сравнение!$O$5:$O$14)-Сравнение!O11)/(MAX(Сравнение!$O$5:$O$14)-MIN(Сравнение!$O$5:$O$14)))) | E11: =IF(OR(NOT(ISNUMBER(Сравнение!P11)),COUNT(Сравнение!$P$5:$P$14)<2),"",IF(MAX(Сравнение!$P$5:$P$14)=MIN(Сравнение!$P$5:$P$14),0.5,(MAX(Сравнение!$P$5:$P$14)-Сравнение!P11)/(MAX(Сравнение!$P$5:$P$14)-MIN(Сравнение!$P$5:$P$14)))) | F11: =IF(OR(NOT(ISNUMBER(Сравнение!J11)),COUNT(Сравнение!$J$5:$J$14)<2),"",IF(MAX(Сравнение!$J$5:$J$14)=MIN(Сравнение!$J$5:$J$14),0.5,(Сравнение!J11-MIN(Сравнение!$J$5:$J$14))/(MAX(Сравнение!$J$5:$J$14)-MIN(Сравнение!$J$5:$J$14)))) | G11: =IF(OR(NOT(ISNUMBER(Сравнение!K11)),COUNT(Сравнение!$K$5:$K$14)<2),"",IF(MAX(Сравнение!$K$5:$K$14)=MIN(Сравнение!$K$5:$K$14),0.5,(MAX(Сравнение!$K$5:$K$14)-Сравнение!K11)/(MAX(Сравнение!$K$5:$K$14)-MIN(Сравнение!$K$5:$K$14)))) | H11: =IF(OR(NOT(ISNUMBER(Сравнение!Q11)),COUNT(Сравнение!$Q$5:$Q$14)<2),"",IF(MAX(Сравнение!$Q$5:$Q$14)=MIN(Сравнение!$Q$5:$Q$14),0.5,(MAX(Сравнение!$Q$5:$Q$14)-Сравнение!Q11)/(MAX(Сравнение!$Q$5:$Q$14)-MIN(Сравнение!$Q$5:$Q$14)))) | I11: =IF(OR(NOT(ISNUMBER(Сравнение!L11)),COUNT(Сравнение!$L$5:$L$14)<2),"",IF(MAX(Сравнение!$L$5:$L$14)=MIN(Сравнение!$L$5:$L$14),0.5,(Сравнение!L11-MIN(Сравнение!$L$5:$L$14))/(MAX(Сравнение!$L$5:$L$14)-MIN(Сравнение!$L$5:$L$14)))) | K11: =IF(OR(Сравнение!A11="",SUM(T11:AA11)=0),"",100*SUM(L11:S11)/SUM(T11:AA11)) | L11: =IF(ISNUMBER(B11),B11*Веса!$B$4,0) | M11: =IF(ISNUMBER(C11),C11*Веса!$B$5,0) | N11: =IF(ISNUMBER(D11),D11*Веса!$B$6,0) | O11: =IF(ISNUMBER(E11),E11*Веса!$B$7,0) | P11: =IF(ISNUMBER(F11),F11*Веса!$B$8,0) | Q11: =IF(ISNUMBER(G11),G11*Веса!$B$9,0) | R11: =IF(ISNUMBER(H11),H11*Веса!$B$10,0) | S11: =IF(ISNUMBER(I11),I11*Веса!$B$11,0) | T11: =IF(ISNUMBER(B11),Веса!$B$4,0) | U11: =IF(ISNUMBER(C11),Веса!$B$5,0) | V11: =IF(ISNUMBER(D11),Веса!$B$6,0) | W11: =IF(ISNUMBER(E11),Веса!$B$7,0) | X11: =IF(ISNUMBER(F11),Веса!$B$8,0) | Y11: =IF(ISNUMBER(G11),Веса!$B$9,0) | Z11: =IF(ISNUMBER(H11),Веса!$B$10,0) | AA11: =IF(ISNUMBER(I11),Веса!$B$11,0)
A12: =IF(Сравнение!A12="","",Сравнение!A12) | B12: =IF(OR(NOT(ISNUMBER(Сравнение!M12)),COUNT(Сравнение!$M$5:$M$14)<2),"",IF(MAX(Сравнение!$M$5:$M$14)=MIN(Сравнение!$M$5:$M$14),0.5,(Сравнение!M12-MIN(Сравнение!$M$5:$M$14))/(MAX(Сравнение!$M$5:$M$14)-MIN(Сравнение!$M$5:$M$14)))) | C12: =IF(OR(NOT(ISNUMBER(Сравнение!N12)),COUNT(Сравнение!$N$5:$N$14)<2),"",IF(MAX(Сравнение!$N$5:$N$14)=MIN(Сравнение!$N$5:$N$14),0.5,(Сравнение!N12-MIN(Сравнение!$N$5:$N$14))/(MAX(Сравнение!$N$5:$N$14)-MIN(Сравнение!$N$5:$N$14)))) | D12: =IF(OR(NOT(ISNUMBER(Сравнение!O12)),COUNT(Сравнение!$O$5:$O$14)<2),"",IF(MAX(Сравнение!$O$5:$O$14)=MIN(Сравнение!$O$5:$O$14),0.5,(MAX(Сравнение!$O$5:$O$14)-Сравнение!O12)/(MAX(Сравнение!$O$5:$O$14)-MIN(Сравнение!$O$5:$O$14)))) | E12: =IF(OR(NOT(ISNUMBER(Сравнение!P12)),COUNT(Сравнение!$P$5:$P$14)<2),"",IF(MAX(Сравнение!$P$5:$P$14)=MIN(Сравнение!$P$5:$P$14),0.5,(MAX(Сравнение!$P$5:$P$14)-Сравнение!P12)/(MAX(Сравнение!$P$5:$P$14)-MIN(Сравнение!$P$5:$P$14)))) | F12: =IF(OR(NOT(ISNUMBER(Сравнение!J12)),COUNT(Сравнение!$J$5:$J$14)<2),"",IF(MAX(Сравнение!$J$5:$J$14)=MIN(Сравнение!$J$5:$J$14),0.5,(Сравнение!J12-MIN(Сравнение!$J$5:$J$14))/(MAX(Сравнение!$J$5:$J$14)-MIN(Сравнение!$J$5:$J$14)))) | G12: =IF(OR(NOT(ISNUMBER(Сравнение!K12)),COUNT(Сравнение!$K$5:$K$14)<2),"",IF(MAX(Сравнение!$K$5:$K$14)=MIN(Сравнение!$K$5:$K$14),0.5,(MAX(Сравнение!$K$5:$K$14)-Сравнение!K12)/(MAX(Сравнение!$K$5:$K$14)-MIN(Сравнение!$K$5:$K$14)))) | H12: =IF(OR(NOT(ISNUMBER(Сравнение!Q12)),COUNT(Сравнение!$Q$5:$Q$14)<2),"",IF(MAX(Сравнение!$Q$5:$Q$14)=MIN(Сравнение!$Q$5:$Q$14),0.5,(MAX(Сравнение!$Q$5:$Q$14)-Сравнение!Q12)/(MAX(Сравнение!$Q$5:$Q$14)-MIN(Сравнение!$Q$5:$Q$14)))) | I12: =IF(OR(NOT(ISNUMBER(Сравнение!L12)),COUNT(Сравнение!$L$5:$L$14)<2),"",IF(MAX(Сравнение!$L$5:$L$14)=MIN(Сравнение!$L$5:$L$14),0.5,(Сравнение!L12-MIN(Сравнение!$L$5:$L$14))/(MAX(Сравнение!$L$5:$L$14)-MIN(Сравнение!$L$5:$L$14)))) | K12: =IF(OR(Сравнение!A12="",SUM(T12:AA12)=0),"",100*SUM(L12:S12)/SUM(T12:AA12)) | L12: =IF(ISNUMBER(B12),B12*Веса!$B$4,0) | M12: =IF(ISNUMBER(C12),C12*Веса!$B$5,0) | N12: =IF(ISNUMBER(D12),D12*Веса!$B$6,0) | O12: =IF(ISNUMBER(E12),E12*Веса!$B$7,0) | P12: =IF(ISNUMBER(F12),F12*Веса!$B$8,0) | Q12: =IF(ISNUMBER(G12),G12*Веса!$B$9,0) | R12: =IF(ISNUMBER(H12),H12*Веса!$B$10,0) | S12: =IF(ISNUMBER(I12),I12*Веса!$B$11,0) | T12: =IF(ISNUMBER(B12),Веса!$B$4,0) | U12: =IF(ISNUMBER(C12),Веса!$B$5,0) | V12: =IF(ISNUMBER(D12),Веса!$B$6,0) | W12: =IF(ISNUMBER(E12),Веса!$B$7,0) | X12: =IF(ISNUMBER(F12),Веса!$B$8,0) | Y12: =IF(ISNUMBER(G12),Веса!$B$9,0) | Z12: =IF(ISNUMBER(H12),Веса!$B$10,0) | AA12: =IF(ISNUMBER(I12),Веса!$B$11,0)
A13: =IF(Сравнение!A13="","",Сравнение!A13) | B13: =IF(OR(NOT(ISNUMBER(Сравнение!M13)),COUNT(Сравнение!$M$5:$M$14)<2),"",IF(MAX(Сравнение!$M$5:$M$14)=MIN(Сравнение!$M$5:$M$14),0.5,(Сравнение!M13-MIN(Сравнение!$M$5:$M$14))/(MAX(Сравнение!$M$5:$M$14)-MIN(Сравнение!$M$5:$M$14)))) | C13: =IF(OR(NOT(ISNUMBER(Сравнение!N13)),COUNT(Сравнение!$N$5:$N$14)<2),"",IF(MAX(Сравнение!$N$5:$N$14)=MIN(Сравнение!$N$5:$N$14),0.5,(Сравнение!N13-MIN(Сравнение!$N$5:$N$14))/(MAX(Сравнение!$N$5:$N$14)-MIN(Сравнение!$N$5:$N$14)))) | D13: =IF(OR(NOT(ISNUMBER(Сравнение!O13)),COUNT(Сравнение!$O$5:$O$14)<2),"",IF(MAX(Сравнение!$O$5:$O$14)=MIN(Сравнение!$O$5:$O$14),0.5,(MAX(Сравнение!$O$5:$O$14)-Сравнение!O13)/(MAX(Сравнение!$O$5:$O$14)-MIN(Сравнение!$O$5:$O$14)))) | E13: =IF(OR(NOT(ISNUMBER(Сравнение!P13)),COUNT(Сравнение!$P$5:$P$14)<2),"",IF(MAX(Сравнение!$P$5:$P$14)=MIN(Сравнение!$P$5:$P$14),0.5,(MAX(Сравнение!$P$5:$P$14)-Сравнение!P13)/(MAX(Сравнение!$P$5:$P$14)-MIN(Сравнение!$P$5:$P$14)))) | F13: =IF(OR(NOT(ISNUMBER(Сравнение!J13)),COUNT(Сравнение!$J$5:$J$14)<2),"",IF(MAX(Сравнение!$J$5:$J$14)=MIN(Сравнение!$J$5:$J$14),0.5,(Сравнение!J13-MIN(Сравнение!$J$5:$J$14))/(MAX(Сравнение!$J$5:$J$14)-MIN(Сравнение!$J$5:$J$14)))) | G13: =IF(OR(NOT(ISNUMBER(Сравнение!K13)),COUNT(Сравнение!$K$5:$K$14)<2),"",IF(MAX(Сравнение!$K$5:$K$14)=MIN(Сравнение!$K$5:$K$14),0.5,(MAX(Сравнение!$K$5:$K$14)-Сравнение!K13)/(MAX(Сравнение!$K$5:$K$14)-MIN(Сравнение!$K$5:$K$14)))) | H13: =IF(OR(NOT(ISNUMBER(Сравнение!Q13)),COUNT(Сравнение!$Q$5:$Q$14)<2),"",IF(MAX(Сравнение!$Q$5:$Q$14)=MIN(Сравнение!$Q$5:$Q$14),0.5,(MAX(Сравнение!$Q$5:$Q$14)-Сравнение!Q13)/(MAX(Сравнение!$Q$5:$Q$14)-MIN(Сравнение!$Q$5:$Q$14)))) | I13: =IF(OR(NOT(ISNUMBER(Сравнение!L13)),COUNT(Сравнение!$L$5:$L$14)<2),"",IF(MAX(Сравнение!$L$5:$L$14)=MIN(Сравнение!$L$5:$L$14),0.5,(Сравнение!L13-MIN(Сравнение!$L$5:$L$14))/(MAX(Сравнение!$L$5:$L$14)-MIN(Сравнение!$L$5:$L$14)))) | K13: =IF(OR(Сравнение!A13="",SUM(T13:AA13)=0),"",100*SUM(L13:S13)/SUM(T13:AA13)) | L13: =IF(ISNUMBER(B13),B13*Веса!$B$4,0) | M13: =IF(ISNUMBER(C13),C13*Веса!$B$5,0) | N13: =IF(ISNUMBER(D13),D13*Веса!$B$6,0) | O13: =IF(ISNUMBER(E13),E13*Веса!$B$7,0) | P13: =IF(ISNUMBER(F13),F13*Веса!$B$8,0) | Q13: =IF(ISNUMBER(G13),G13*Веса!$B$9,0) | R13: =IF(ISNUMBER(H13),H13*Веса!$B$10,0) | S13: =IF(ISNUMBER(I13),I13*Веса!$B$11,0) | T13: =IF(ISNUMBER(B13),Веса!$B$4,0) | U13: =IF(ISNUMBER(C13),Веса!$B$5,0) | V13: =IF(ISNUMBER(D13),Веса!$B$6,0) | W13: =IF(ISNUMBER(E13),Веса!$B$7,0) | X13: =IF(ISNUMBER(F13),Веса!$B$8,0) | Y13: =IF(ISNUMBER(G13),Веса!$B$9,0) | Z13: =IF(ISNUMBER(H13),Веса!$B$10,0) | AA13: =IF(ISNUMBER(I13),Веса!$B$11,0)
A14: =IF(Сравнение!A14="","",Сравнение!A14) | B14: =IF(OR(NOT(ISNUMBER(Сравнение!M14)),COUNT(Сравнение!$M$5:$M$14)<2),"",IF(MAX(Сравнение!$M$5:$M$14)=MIN(Сравнение!$M$5:$M$14),0.5,(Сравнение!M14-MIN(Сравнение!$M$5:$M$14))/(MAX(Сравнение!$M$5:$M$14)-MIN(Сравнение!$M$5:$M$14)))) | C14: =IF(OR(NOT(ISNUMBER(Сравнение!N14)),COUNT(Сравнение!$N$5:$N$14)<2),"",IF(MAX(Сравнение!$N$5:$N$14)=MIN(Сравнение!$N$5:$N$14),0.5,(Сравнение!N14-MIN(Сравнение!$N$5:$N$14))/(MAX(Сравнение!$N$5:$N$14)-MIN(Сравнение!$N$5:$N$14)))) | D14: =IF(OR(NOT(ISNUMBER(Сравнение!O14)),COUNT(Сравнение!$O$5:$O$14)<2),"",IF(MAX(Сравнение!$O$5:$O$14)=MIN(Сравнение!$O$5:$O$14),0.5,(MAX(Сравнение!$O$5:$O$14)-Сравнение!O14)/(MAX(Сравнение!$O$5:$O$14)-MIN(Сравнение!$O$5:$O$14)))) | E14: =IF(OR(NOT(ISNUMBER(Сравнение!P14)),COUNT(Сравнение!$P$5:$P$14)<2),"",IF(MAX(Сравнение!$P$5:$P$14)=MIN(Сравнение!$P$5:$P$14),0.5,(MAX(Сравнение!$P$5:$P$14)-Сравнение!P14)/(MAX(Сравнение!$P$5:$P$14)-MIN(Сравнение!$P$5:$P$14)))) | F14: =IF(OR(NOT(ISNUMBER(Сравнение!J14)),COUNT(Сравнение!$J$5:$J$14)<2),"",IF(MAX(Сравнение!$J$5:$J$14)=MIN(Сравнение!$J$5:$J$14),0.5,(Сравнение!J14-MIN(Сравнение!$J$5:$J$14))/(MAX(Сравнение!$J$5:$J$14)-MIN(Сравнение!$J$5:$J$14)))) | G14: =IF(OR(NOT(ISNUMBER(Сравнение!K14)),COUNT(Сравнение!$K$5:$K$14)<2),"",IF(MAX(Сравнение!$K$5:$K$14)=MIN(Сравнение!$K$5:$K$14),0.5,(MAX(Сравнение!$K$5:$K$14)-Сравнение!K14)/(MAX(Сравнение!$K$5:$K$14)-MIN(Сравнение!$K$5:$K$14)))) | H14: =IF(OR(NOT(ISNUMBER(Сравнение!Q14)),COUNT(Сравнение!$Q$5:$Q$14)<2),"",IF(MAX(Сравнение!$Q$5:$Q$14)=MIN(Сравнение!$Q$5:$Q$14),0.5,(MAX(Сравнение!$Q$5:$Q$14)-Сравнение!Q14)/(MAX(Сравнение!$Q$5:$Q$14)-MIN(Сравнение!$Q$5:$Q$14)))) | I14: =IF(OR(NOT(ISNUMBER(Сравнение!L14)),COUNT(Сравнение!$L$5:$L$14)<2),"",IF(MAX(Сравнение!$L$5:$L$14)=MIN(Сравнение!$L$5:$L$14),0.5,(Сравнение!L14-MIN(Сравнение!$L$5:$L$14))/(MAX(Сравнение!$L$5:$L$14)-MIN(Сравнение!$L$5:$L$14)))) | K14: =IF(OR(Сравнение!A14="",SUM(T14:AA14)=0),"",100*SUM(L14:S14)/SUM(T14:AA14)) | L14: =IF(ISNUMBER(B14),B14*Веса!$B$4,0) | M14: =IF(ISNUMBER(C14),C14*Веса!$B$5,0) | N14: =IF(ISNUMBER(D14),D14*Веса!$B$6,0) | O14: =IF(ISNUMBER(E14),E14*Веса!$B$7,0) | P14: =IF(ISNUMBER(F14),F14*Веса!$B$8,0) | Q14: =IF(ISNUMBER(G14),G14*Веса!$B$9,0) | R14: =IF(ISNUMBER(H14),H14*Веса!$B$10,0) | S14: =IF(ISNUMBER(I14),I14*Веса!$B$11,0) | T14: =IF(ISNUMBER(B14),Веса!$B$4,0) | U14: =IF(ISNUMBER(C14),Веса!$B$5,0) | V14: =IF(ISNUMBER(D14),Веса!$B$6,0) | W14: =IF(ISNUMBER(E14),Веса!$B$7,0) | X14: =IF(ISNUMBER(F14),Веса!$B$8,0) | Y14: =IF(ISNUMBER(G14),Веса!$B$9,0) | Z14: =IF(ISNUMBER(H14),Веса!$B$10,0) | AA14: =IF(ISNUMBER(I14),Веса!$B$11,0)

Sheet Веса
A1: Веса метрик (меняй под себя)
A3: Метрика | B3: Вес | C3: Направление
A4: Рост TVL 6м | B4: 15 | C4: больше = лучше
A5: Рост адресов 6м | B5: 15 | C5: больше = лучше
A6: Mcap / TVL | B6: 10 | C6: меньше = лучше
A7: Mcap / Доход | B7: 15 | C7: меньше = лучше
A8: Активных разработчиков | B8: 15 | C8: больше = лучше
A9: Разлок за 6 мес | B9: 10 | C9: меньше = лучше
A10: FDV / Mcap | B10: 10 | C10: меньше = лучше
A11: Инвесторы и команда | B11: 10 | C11: больше = лучше
A12: Сумма весов | B12: =SUM(B4:B11)

Sheet Инструкция
A1: Где брать цифры
A3: Колонка | B3: Источник | C3: Ссылка
A4: Капитализация, FDV | B4: CoinGecko | C4: https://www.coingecko.com/en/categories
A5: TVL сейчас и 6 мес назад | B5: DeFiLlama → Chains | C5: https://defillama.com/chains
A6: Активные адреса | B6: Artemis | C6: https://app.artemis.xyz
A7: Доход / комиссии | B7: DeFiLlama Fees | C7: https://defillama.com/fees
A8: Доход (альтернатива) | B8: Token Terminal | C8: https://tokenterminal.com
A9: Разработчики | B9: Artemis | C9: https://app.artemis.xyz
A10: Разлоки | B10: Tokenomist | C10: https://tokenomist.ai
A11: Инвесторы, раунды | B11: CryptoRank | C11: https://cryptorank.io
A12: Инвесторы, раунды | B12: DeFiLlama Raises | C12: https://defillama.com/raises
A13: Метрики L2 | B13: growthepie | C13: https://www.growthepie.xyz
A14: Риски L2 | B14: L2BEAT | C14: https://l2beat.com
A17: Как пользоваться:
A18: 1. На листе «Сравнение» замени строки «Пример» своими сетями (до 10 штук).
A19: 2. Заполняй жёлтые ячейки. Пустые метрики просто не учитываются в балле.
A20: 3. Для балла нужно минимум 2 сети с данными по метрике.
A21: 4. Веса метрик меняй на листе «Веса».
A22: 5. Разлок вводи в процентах (3% = 3%), инвесторов — оценкой 1–5 по своему мнению.
A23: Балл относительный и не является рекомендацией к покупке.

Sheet Источники
A1: Откуда взята каждая цифра (сбор 30.09.2026)
A3: Экосистема | B3: Метрика | C3: Значение | D3: Источник | E3: Комментарий
A4: Arbitrum | B4: Капитализация, $ млн | C4: 1372.0642 | D4: CoinGecko
A5: Arbitrum | B5: FDV, $ млн | C5: 2022.031 | D5: CoinGecko
A6: Arbitrum | B6: TVL сейчас, $ млн | C6: 1440.3621 | D6: DeFiLlama | E6: на 2026-09-30
A7: Arbitrum | B7: TVL 6 мес назад, $ млн | C7: 1926.9911 | D7: DeFiLlama | E7: на 2026-04-01
A8: Arbitrum | B8: Активные адреса/день сейчас | C8: 135118 | D8: Artemis | E8: медиана за 7 дн до 2026-09-29
A9: Arbitrum | B9: Активные адреса/день 6 мес назад | C9: 161371 | D9: Artemis | E9: медиана за 7 дн до 2026-04-01
A10: Arbitrum | B10: Доход/комиссии за год, $ млн | C10: 10.394479 | D10: DeFiLlama | E10: комиссии за 365 дн (Arbitrum)
A11: Arbitrum | B11: Активных разработчиков/мес | D11: нет данных — заполнить вручную
A12: Arbitrum | B12: Разлок за 6 мес, % предложения | D12: нет данных — заполнить вручную
A13: Arbitrum | B13: Инвесторы и команда, 1–5 | D13: нет данных — заполнить вручную
A14: Optimism | B14: Капитализация, $ млн | C14: 299.60174 | D14: CoinGecko
A15: Optimism | B15: FDV, $ млн | C15: 559.56066 | D15: CoinGecko
A16: Optimism | B16: TVL сейчас, $ млн | C16: 488.95365 | D16: DeFiLlama | E16: на 2026-09-30
A17: Optimism | B17: TVL 6 мес назад, $ млн | C17: 195.62457 | D17: DeFiLlama | E17: на 2026-04-01
A18: Optimism | B18: Активные адреса/день сейчас | C18: 35710 | D18: Artemis | E18: медиана за 7 дн до 2026-09-29
A19: Optimism | B19: Активные адреса/день 6 мес назад | C19: 18509 | D19: Artemis | E19: медиана за 7 дн до 2026-04-01
A20: Optimism | B20: Доход/комиссии за год, $ млн | C20: 1.163975 | D20: DeFiLlama | E20: комиссии за 365 дн (OP Mainnet)
A21: Optimism | B21: Активных разработчиков/мес | D21: нет данных — заполнить вручную
A22: Optimism | B22: Разлок за 6 мес, % предложения | D22: нет данных — заполнить вручную
A23: Optimism | B23: Инвесторы и команда, 1–5 | D23: нет данных — заполнить вручную
A24: Base | B24: Капитализация, $ млн | D24: нет данных — заполнить вручную
A25: Base | B25: FDV, $ млн | D25: нет данных — заполнить вручную
A26: Base | B26: TVL сейчас, $ млн | C26: 6361.8884 | D26: DeFiLlama | E26: на 2026-09-30
A27: Base | B27: TVL 6 мес назад, $ млн | C27: 4057.3668 | D27: DeFiLlama | E27: на 2026-04-01
A28: Base | B28: Активные адреса/день сейчас | C28: 308996 | D28: Artemis | E28: медиана за 7 дн до 2026-09-29
A29: Base | B29: Активные адреса/день 6 мес назад | C29: 424000 | D29: Artemis | E29: медиана за 7 дн до 2026-04-01
A30: Base | B30: Доход/комиссии за год, $ млн | C30: 56.624755 | D30: DeFiLlama | E30: комиссии за 365 дн (Base)
A31: Base | B31: Активных разработчиков/мес | D31: нет данных — заполнить вручную
A32: Base | B32: Разлок за 6 мес, % предложения | D32: нет данных — заполнить вручную
A33: Base | B33: Инвесторы и команда, 1–5 | D33: нет данных — заполнить вручную
A34: Mantle | B34: Капитализация, $ млн | C34: 2303.632 | D34: CoinGecko
A35: Mantle | B35: FDV, $ млн | C35: 4338.504 | D35: CoinGecko
A36: Mantle | B36: TVL сейчас, $ млн | C36: 105.98936 | D36: DeFiLlama | E36: на 2026-09-30
A37: Mantle | B37: TVL 6 мес назад, $ млн | C37: 653.48033 | D37: DeFiLlama | E37: на 2026-04-01
A38: Mantle | B38: Активные адреса/день сейчас | C38: 1300 | D38: Artemis | E38: медиана за 7 дн до 2026-09-29
A39: Mantle | B39: Активные адреса/день 6 мес назад | C39: 1499 | D39: Artemis | E39: медиана за 7 дн до 2026-04-01
A40: Mantle | B40: Доход/комиссии за год, $ млн | C40: 0.252569 | D40: DeFiLlama | E40: комиссии за 365 дн (Mantle)
A41: Mantle | B41: Активных разработчиков/мес | D41: нет данных — заполнить вручную
...
